Workbook

Sheet Time Tracking
A1: Date | B1: Company | C1: Project Name | D1: Start Time | E1: End Time | F1: Short Description | G1: Detailed Description | H1: Project Activity | I1: Show Time As | J1: Location | K1: Business Unit | L1: Logged | M1: {=_xlfn.TEXTSPLIT(_xlfn.TEXTJOIN(",",TRUE,_xlfn._xlws.FILTER('Active Projects'!B:B, 'Active Projects'!A:A=INDIRECT("B"&ROW()))),",")} -> Project
A2: 45964 | B2: Floracraft | C2: Floracraft-Azure Landing Zone | D2: 14 | E2: 15 | F2: Design Blueprint | G2: Design Blueprint | H2: Engineering | I2: Assigned Project | J2: Sentinel or Home Office | K2: Enterprise Applications | M2: {=_xlfn.TEXTSPLIT(_xlfn.TEXTJOIN(",",TRUE,_xlfn._xlws.FILTER('Active Projects'!B:B, 'Active Projects'!A:A=INDIRECT("B"&ROW()))),",")} -> Floracraft-Azure Landing Zone | N2: Floracraft-Azure Server Migrations
A3: 45964 | B3: Credit Interlink | C3: Credit Interlink-Production to Azure Migration T_M | D3: 15 | E3: 15.5 | F3: Status Update | G3: Status Update | H3: Engineering | I3: Assigned Project | J3: Sentinel or Home Office | K3: Enterprise Applications | M3: {=_xlfn.TEXTSPLIT(_xlfn.TEXTJOIN(",",TRUE,_xlfn._xlws.FILTER('Active Projects'!B:B, 'Active Projects'!A:A=INDIRECT("B"&ROW()))),",")} -> Credit Interlink-Production to Azure Migration T_M | N3: Credit Interlink-DR_HA Configuration
A4: 45964 | B4: cr Holdings Inc | C4: QCR Holdings-Azure Event Hub | D4: 15.5 | E4: 16 | F4: IKO | G4: IKO | H4: Engineering | I4: Assigned Project | J4: Sentinel or Home Office | K4: Enterprise Applications | M4: {=_xlfn.TEXTSPLIT(_xlfn.TEXTJOIN(",",TRUE,_xlfn._xlws.FILTER('Active Projects'!B:B, 'Active Projects'!A:A=INDIRECT("B"&ROW()))),",")} -> QCR Holdings-Azure Event Hub
A5: 45964 | B5: Floracraft | C5: Floracraft-Azure Landing Zone | D5: 16 | E5: 16.5 | F5: Design Blueprint | G5: Design Blueprint | H5: Engineering | I5: Assigned Project | J5: Sentinel or Home Office | K5: Enterprise Applications | M5: {=_xlfn.TEXTSPLIT(_xlfn.TEXTJOIN(",",TRUE,_xlfn._xlws.FILTER('Active Projects'!B:B, 'Active Projects'!A:A=INDIRECT("B"&ROW()))),",")} -> Floracraft-Azure Landing Zone | N5: Floracraft-Azure Server Migrations
A6: 45965 | B6: Floracraft | C6: Floracraft-Azure Landing Zone | D6: 8.5 | E6: 9 | F6: Design Blueprint | G6: Design Blueprint | H6: Engineering | I6: Assigned Project | J6: Sentinel or Home Office | K6: Enterprise Applications | M6: {=_xlfn.TEXTSPLIT(_xlfn.TEXTJOIN(",",TRUE,_xlfn._xlws.FILTER('Active Projects'!B:B, 'Active Projects'!A:A=INDIRECT("B"&ROW()))),",")} -> Floracraft-Azure Landing Zone | N6: Floracraft-Azure Server Migrations
A7: 45965 | B7: Aurorium | C7: Aurorium-Azure Services | D7: 9 | E7: 9.5 | F7: Internal Sync | G7: Internal Sync | H7: Engineering | I7: Assigned Project | J7: Sentinel or Home Office | K7: Enterprise Applications | M7: {=_xlfn.TEXTSPLIT(_xlfn.TEXTJOIN(",",TRUE,_xlfn._xlws.FILTER('Active Projects'!B:B, 'Active Projects'!A:A=INDIRECT("B"&ROW()))),",")} -> Aurorium-Azure Services
A8: 45965 | B8: Floracraft | C8: Floracraft-Azure Landing Zone | D8: 9.5 | E8: 10 | F8: Design Blueprint | G8: Design Blueprint | H8: Engineering | I8: Assigned Project | J8: Sentinel or Home Office | K8: Enterprise Applications | M8: {=_xlfn.TEXTSPLIT(_xlfn.TEXTJOIN(",",TRUE,_xlfn._xlws.FILTER('Active Projects'!B:B, 'Active Projects'!A:A=INDIRECT("B"&ROW()))),",")} -> Floracraft-Azure Landing Zone | N8: Floracraft-Azure Server Migrations
A9: 45965 | B9: Clark County Library District | C9: Clark County Library District-Azure Accelerate Assessment | D9: 10 | E9: 11 | F9: Deliverable Generation | G9: Deliverable | H9: Engineering | I9: Assigned Project | J9: Sentinel or Home Office | K9: Enterprise Applications | M9: {=_xlfn.TEXTSPLIT(_xlfn.TEXTJOIN(",",TRUE,_xlfn._xlws.FILTER('Active Projects'!B:B, 'Active Projects'!A:A=INDIRECT("B"&ROW()))),",")} -> Clark County Library District-Azure Accelerate Assessment
A10: 45965 | B10: SPAR Group Inc | C10: SPAR Group-Server Project Design | D10: 11 | E10: 11.5 | F10: Internal Sync | G10: Internal Sync | H10: Engineering | I10: Assigned Project | J10: Sentinel or Home Office | K10: Enterprise Applications | M10: {=_xlfn.TEXTSPLIT(_xlfn.TEXTJOIN(",",TRUE,_xlfn._xlws.FILTER('Active Projects'!B:B, 'Active Projects'!A:A=INDIRECT("B"&ROW()))),",")} -> SPAR Group-Server Project Design | N10: SPAR Group-Server Project Build and Migration
A11: 45965 | B11: National Council of State Boards of Nursing | C11: National Council of State Boards of Nursing-Microsoft Resource | D11: 11.5 | E11: 12 | F11: Team Meeting | G11: Team Meeting | H11: Engineering | I11: Assigned Project | J11: Sentinel or Home Office | K11: Enterprise Applications | M11: {=_xlfn.TEXTSPLIT(_xlfn.TEXTJOIN(",",TRUE,_xlfn._xlws.FILTER('Active Projects'!B:B, 'Active Projects'!A:A=INDIRECT("B"&ROW()))),",")} -> National Council of State Boards of Nursing-Microsoft Resource
A12: 45965 | B12: L.E.K. Consulting LLC | C12: L.E.K Consulting-Azure Networking Assessment | D12: 14 | E12: 16 | F12: Network Review | G12: Network Review | H12: Engineering | I12: Assigned Project | J12: Sentinel or Home Office | K12: Enterprise Applications | M12: {=_xlfn.TEXTSPLIT(_xlfn.TEXTJOIN(",",TRUE,_xlfn._xlws.FILTER('Active Projects'!B:B, 'Active Projects'!A:A=INDIRECT("B"&ROW()))),",")} -> L.E.K Consulting-Azure Networking Assessment
A13: 45965 | B13: WK Kellogg Co. | C13: WK Kellogg-AVD and Windows 365 | D13: 16 | E13: 16.5 | F13: Review Deliverable / Meeting Prep | G13: Review Deliverable / Meeting Prep | H13: Engineering | I13: Assigned Project | J13: Sentinel or Home Office | K13: Enterprise Applications | M13: {=_xlfn.TEXTSPLIT(_xlfn.TEXTJOIN(",",TRUE,_xlfn._xlws.FILTER('Active Projects'!B:B, 'Active Projects'!A:A=INDIRECT("B"&ROW()))),",")} -> WK Kellogg-AVD and Windows 365
A14: 45966 | B14: L.E.K. Consulting LLC | C14: L.E.K Consulting-Azure Networking Assessment | D14: 9 | E14: 9.75 | F14: Network Review | G14: Network Review | H14: Engineering | I14: Assigned Project | J14: Sentinel or Home Office | K14: Enterprise Applications | M14: {=_xlfn.TEXTSPLIT(_xlfn.TEXTJOIN(",",TRUE,_xlfn._xlws.FILTER('Active Projects'!B:B, 'Active Projects'!A:A=INDIRECT("B"&ROW()))),",")} -> L.E.K Consulting-Azure Networking Assessment
A15: 45966 | B15: National Council of State Boards of Nursing | D15: 10 | E15: 11.5 | F15: ASP Review | G15: ASP Review | H15: Engineering | I15: Assigned Project | J15: Sentinel or Home Office | K15: Enterprise Applications | M15: {=_xlfn.TEXTSPLIT(_xlfn.TEXTJOIN(",",TRUE,_xlfn._xlws.FILTER('Active Projects'!B:B, 'Active Projects'!A:A=INDIRECT("B"&ROW()))),",")} -> National Council of State Boards of Nursing-Microsoft Resource
A16: 45966 | B16: Aurorium | C16: Aurorium-Azure Services | D16: 11.5 | E16: 12 | F16: Status Update | G16: Status Update | H16: Engineering | I16: Assigned Project | J16: Sentinel or Home Office | K16: Enterprise Applications | M16: {=_xlfn.TEXTSPLIT(_xlfn.TEXTJOIN(",",TRUE,_xlfn._xlws.FILTER('Active Projects'!B:B, 'Active Projects'!A:A=INDIRECT("B"&ROW()))),",")} -> Aurorium-Azure Services
A17: 45966 | B17: SPAR Group Inc | C17: SPAR Group-Server Project Design | D17: 12 | E17: 12.25 | F17: Verify Creds | G17: Verify Creds | H17: Engineering | I17: Assigned Project | J17: Sentinel or Home Office | K17: Enterprise Applications | M17: {=_xlfn.TEXTSPLIT(_xlfn.TEXTJOIN(",",TRUE,_xlfn._xlws.FILTER('Active Projects'!B:B, 'Active Projects'!A:A=INDIRECT("B"&ROW()))),",")} -> SPAR Group-Server Project Design | N17: SPAR Group-Server Project Build and Migration
A18: 45966 | B18: SPAR Group Inc | C18: SPAR Group-Server Project Design | D18: 13 | E18: 15 | F18: Discovery | G18: Discovery | H18: Engineering | I18: Assigned Project | J18: Sentinel or Home Office | K18: Enterprise Applications | M18: {=_xlfn.TEXTSPLIT(_xlfn.TEXTJOIN(",",TRUE,_xlfn._xlws.FILTER('Active Projects'!B:B, 'Active Projects'!A:A=INDIRECT("B"&ROW()))),",")} -> SPAR Group-Server Project Design | N18: SPAR Group-Server Project Build and Migration
A19: 45966 | B19: City Of Des Plaines | C19: City of Des Plaines-Azure Domain Controller Migration | D19: 15 | E19: 15.5 | F19: Status Update and Design Review | G19: Status Update and Design Review | H19: Engineering | I19: Assigned Project | J19: Sentinel or Home Office | K19: Enterprise Applications | M19: {=_xlfn.TEXTSPLIT(_xlfn.TEXTJOIN(",",TRUE,_xlfn._xlws.FILTER('Active Projects'!B:B, 'Active Projects'!A:A=INDIRECT("B"&ROW()))),",")} -> City of Des Plaines-Azure Domain Controller Migration
A20: 45966 | B20: SPAR Group Inc | C20: SPAR Group-Server Project Design | D20: 15.5 | E20: 15.75 | F20: Discovery | G20: Discovery | H20: Engineering | I20: Assigned Project | J20: Sentinel or Home Office | K20: Enterprise Applications | M20: {=_xlfn.TEXTSPLIT(_xlfn.TEXTJOIN(",",TRUE,_xlfn._xlws.FILTER('Active Projects'!B:B, 'Active Projects'!A:A=INDIRECT("B"&ROW()))),",")} -> SPAR Group-Server Project Design | N20: SPAR Group-Server Project Build and Migration
A21: 45966 | B21: WK Kellogg Co. | C21: WK Kellogg-AVD and Windows 365 | D21: 15.75 | E21: 17.25 | F21: Deliverable Presentation | G21: Deliverable Presentation | H21: Engineering | I21: Assigned Project | J21: Sentinel or Home Office | K21: Enterprise Applications | M21: {=_xlfn.TEXTSPLIT(_xlfn.TEXTJOIN(",",TRUE,_xlfn._xlws.FILTER('Active Projects'!B:B, 'Active Projects'!A:A=INDIRECT("B"&ROW()))),",")} -> WK Kellogg-AVD and Windows 365
A22: 45967 | B22: Credit Interlink | C22: Credit Interlink-DR_HA Configuration | D22: 9 | E22: 13 | F22: Discovery Call for Production Deployment | G22: Discovery Call for Production Deployment | H22: Engineering | I22: Assigned Project | J22: Sentinel or Home Office | K22: Enterprise Applications | M22: {=_xlfn.TEXTSPLIT(_xlfn.TEXTJOIN(",",TRUE,_xlfn._xlws.FILTER('Active Projects'!B:B, 'Active Projects'!A:A=INDIRECT("B"&ROW()))),",")} -> Credit Interlink-Production to Azure Migration T_M | N22: Credit Interlink-DR_HA Configuration
A23: 45967 | B23: WK Kellogg Co. | C23: WK Kellogg-AVD and Windows 365 | D23: 14 | E23: 14.5 | F23: Cleanup of monitoring | G23: Cleanup of monitoring | H23: Engineering | I23: Assigned Project | J23: Sentinel or Home Office | K23: Enterprise Applications | M23: {=_xlfn.TEXTSPLIT(_xlfn.TEXTJOIN(",",TRUE,_xlfn._xlws.FILTER('Active Projects'!B:B, 'Active Projects'!A:A=INDIRECT("B"&ROW()))),",")} -> WK Kellogg-AVD and Windows 365
A24: 45967 | B24: SPAR Group Inc | C24: SPAR Group-Server Project Design | D24: 14.5 | E24: 15 | F24: Review ADFS | G24: Review ADFS | H24: Engineering | I24: Assigned Project | J24: Sentinel or Home Office | K24: Enterprise Applications | M24: {=_xlfn.TEXTSPLIT(_xlfn.TEXTJOIN(",",TRUE,_xlfn._xlws.FILTER('Active Projects'!B:B, 'Active Projects'!A:A=INDIRECT("B"&ROW()))),",")} -> SPAR Group-Server Project Design | N24: SPAR Group-Server Project Build and Migration
A25: 45967 | B25: Brightstar Care | C25: Brightstar Care-Azure Network Services | D25: 15 | E25: 15.5 | F25: Status Update | G25: Status Update | H25: Engineering | I25: Assigned Project | J25: Sentinel or Home Office | K25: Enterprise Applications | M25: {=_xlfn.TEXTSPLIT(_xlfn.TEXTJOIN(",",TRUE,_xlfn._xlws.FILTER('Active Projects'!B:B, 'Active Projects'!A:A=INDIRECT("B"&ROW()))),",")} -> Brightstar Care-Azure Network Services | N25: Brightstar Care-Azure Network Services Review Calls
A26: 45967 | B26: SPAR Group Inc | C26: SPAR Group-Server Project Design | D26: 15.5 | E26: 17 | F26: Design Blueprint | G26: Design Blueprint | H26: Engineering | I26: Assigned Project | J26: Sentinel or Home Office | K26: Enterprise Applications | M26: {=_xlfn.TEXTSPLIT(_xlfn.TEXTJOIN(",",TRUE,_xlfn._xlws.FILTER('Active Projects'!B:B, 'Active Projects'!A:A=INDIRECT("B"&ROW()))),",")} -> SPAR Group-Server Project Design | N26: SPAR Group-Server Project Build and Migration
A27: 45968 | B27: Sylvan, Inc | C27: Sylvan-AVD Proof of Concept | D27: 8.5 | E27: 13.5 | F27: Build Personal AVD Pool | G27: Build Personal AVD Pool | H27: Engineering | I27: Assigned Project | J27: Sentinel or Home Office | K27: Enterprise Applications | M27: {=_xlfn.TEXTSPLIT(_xlfn.TEXTJOIN(",",TRUE,_xlfn._xlws.FILTER('Active Projects'!B:B, 'Active Projects'!A:A=INDIRECT("B"&ROW()))),",")} -> Sylvan-AVD Proof of Concept
A28: 45968 | B28: Floracraft | C28: Floracraft-Azure Landing Zone | D28: 14 | E28: 15 | F28: Status Update and Project Planning | G28: Status Update and Project Planning | H28: Engineering | I28: Assigned Project | J28: Sentinel or Home Office | K28: Enterprise Applications | M28: {=_xlfn.TEXTSPLIT(_xlfn.TEXTJOIN(",",TRUE,_xlfn._xlws.FILTER('Active Projects'!B:B, 'Active Projects'!A:A=INDIRECT("B"&ROW()))),",")} -> Floracraft-Azure Landing Zone | N28: Floracraft-Azure Server Migrations
A29: 45968 | B29: Atlas Healthcare Partners | C29: Atlas Healthcare Partners-Windows 365 Jumpstart | D29: 15 | E29: 15.25 | F29: Verify Intune Enrollment | G29: Verify Intune Enrollment | H29: Engineering | I29: Assigned Project | J29: Sentinel or Home Office | K29: Enterprise Applications | M29: {=_xlfn.TEXTSPLIT(_xlfn.TEXTJOIN(",",TRUE,_xlfn._xlws.FILTER('Active Projects'!B:B, 'Active Projects'!A:A=INDIRECT("B"&ROW()))),",")} -> Atlas Healthcare Partners-Windows 365 Jumpstart
A30: 45971 | B30: Aurorium | C30: Aurorium-Azure Services | D30: 6 | E30: 6.5 | F30: Review SOW and meeting prep | G30: Review SOW and meeting prep | H30: Engineering | I30: Assigned Project | J30: Sentinel or Home Office | K30: Enterprise Applications | M30: {=_xlfn.TEXTSPLIT(_xlfn.TEXTJOIN(",",TRUE,_xlfn._xlws.FILTER('Active Projects'!B:B, 'Active Projects'!A:A=INDIRECT("B"&ROW()))),",")} -> Aurorium-Azure Services
A31: 45971 | B31: Credit Interlink | C31: Credit Interlink-DR_HA Configuration | D31: 6.5 | E31: 6.75 | F31: Respond to MS Support Case | G31: Respond to MS Support Case | H31: Engineering | I31: Assigned Project | J31: Sentinel or Home Office | K31: Enterprise Applications | M31: {=_xlfn.TEXTSPLIT(_xlfn.TEXTJOIN(",",TRUE,_xlfn._xlws.FILTER('Active Projects'!B:B, 'Active Projects'!A:A=INDIRECT("B"&ROW()))),",")} -> Credit Interlink-Production to Azure Migration T_M | N31: Credit Interlink-DR_HA Configuration
A32: 45971 | B32: cr Holdings Inc | C32: QCR Holdings-Azure Event Hub | D32: 8.5 | E32: 9 | F32: EKO | G32: EKO | H32: Engineering | I32: Assigned Project | J32: Sentinel or Home Office | K32: Enterprise Applications | M32: {=_xlfn.TEXTSPLIT(_xlfn.TEXTJOIN(",",TRUE,_xlfn._xlws.FILTER('Active Projects'!B:B, 'Active Projects'!A:A=INDIRECT("B"&ROW()))),",")} -> QCR Holdings-Azure Event Hub
A33: 45971 | B33: Aurorium | C33: Aurorium-Azure Services | D33: 9 | E33: 10.25 | F33: Discovery Call | G33: Discover Call | H33: Engineering | I33: Assigned Project | J33: Sentinel or Home Office | K33: Enterprise Applications | M33: {=_xlfn.TEXTSPLIT(_xlfn.TEXTJOIN(",",TRUE,_xlfn._xlws.FILTER('Active Projects'!B:B, 'Active Projects'!A:A=INDIRECT("B"&ROW()))),",")} -> Aurorium-Azure Services
A34: 45971 | B34: Atlas Healthcare Partners | C34: Atlas Healthcare Partners-Windows 365 Jumpstart | D34: 10.75 | E34: 11 | F34: Update Intune Group Membership | G34: Update Intune Group Membership | H34: Engineering | I34: Assigned Project | J34: Sentinel or Home Office | K34: Enterprise Applications | M34: {=_xlfn.TEXTSPLIT(_xlfn.TEXTJOIN(",",TRUE,_xlfn._xlws.FILTER('Active Projects'!B:B, 'Active Projects'!A:A=INDIRECT("B"&ROW()))),",")} -> Atlas Healthcare Partners-Windows 365 Jumpstart
A35: 45971 | B35: Credit Interlink | C35: Credit Interlink-DR_HA Configuration | D35: 11 | E35: 12.75 | F35: Review Design Options | G35: Review Design Options | H35: Engineering | I35: Assigned Project | J35: Sentinel or Home Office | K35: Enterprise Applications | M35: {=_xlfn.TEXTSPLIT(_xlfn.TEXTJOIN(",",TRUE,_xlfn._xlws.FILTER('Active Projects'!B:B, 'Active Projects'!A:A=INDIRECT("B"&ROW()))),",")} -> Credit Interlink-Production to Azure Migration T_M | N35: Credit Interlink-DR_HA Configuration
A36: 45971 | B36: Atlas Healthcare Partners | C36: Atlas Healthcare Partners-Windows 365 Jumpstart | D36: 13.75 | E36: 14.75 | F36: Intune app review | G36: Intune app review | H36: Engineering | I36: Assigned Project | J36: Sentinel or Home Office | K36: Enterprise Applications | M36: {=_xlfn.TEXTSPLIT(_xlfn.TEXTJOIN(",",TRUE,_xlfn._xlws.FILTER('Active Projects'!B:B, 'Active Projects'!A:A=INDIRECT("B"&ROW()))),",")} -> Atlas Healthcare Partners-Windows 365 Jumpstart
A37: 45971 | B37: L.E.K. Consulting LLC | C37: L.E.K Consulting-Azure Networking Assessment | D37: 15 | E37: 15.5 | F37: Status Update | G37: Status Update | H37: Engineering | I37: Assigned Project | J37: Sentinel or Home Office | K37: Enterprise Applications | M37: {=_xlfn.TEXTSPLIT(_xlfn.TEXTJOIN(",",TRUE,_xlfn._xlws.FILTER('Active Projects'!B:B, 'Active Projects'!A:A=INDIRECT("B"&ROW()))),",")} -> L.E.K Consulting-Azure Networking Assessment
A38: 45971 | B38: Atlas Healthcare Partners | C38: Atlas Healthcare Partners-Windows 365 Jumpstart | D38: 15.5 | E38: 16 | F38: Verify Software Installation | G38: Verify Software Installation | H38: Engineering | I38: Assigned Project | J38: Sentinel or Home Office | K38: Enterprise Applications | M38: {=_xlfn.TEXTSPLIT(_xlfn.TEXTJOIN(",",TRUE,_xlfn._xlws.FILTER('Active Projects'!B:B, 'Active Projects'!A:A=INDIRECT("B"&ROW()))),",")} -> Atlas Healthcare Partners-Windows 365 Jumpstart
A39: 45972 | B39: Credit Interlink | C39: Credit Interlink-DR_HA Configuration | D39: 8.5 | E39: 11 | F39: Update proposed architecture | G39: Update proposed architecture | H39: Engineering | I39: Assigned Project | J39: Sentinel or Home Office | K39: Enterprise Applications | M39: {=_xlfn.TEXTSPLIT(_xlfn.TEXTJOIN(",",TRUE,_xlfn._xlws.FILTER('Active Projects'!B:B, 'Active Projects'!A:A=INDIRECT("B"&ROW()))),",")} -> Credit Interlink-Production to Azure Migration T_M | N39: Credit Interlink-DR_HA Configuration
A40: 45972 | B40: SPAR Group Inc | C40: SPAR Group-Server Project Design | D40: 11 | E40: 12 | F40: Update design blueprint | G40: Update design blueprint | H40: Engineering | I40: Assigned Project | J40: Sentinel or Home Office | K40: Enterprise Applications | M40: {=_xlfn.TEXTSPLIT(_xlfn.TEXTJOIN(",",TRUE,_xlfn._xlws.FILTER('Active Projects'!B:B, 'Active Projects'!A:A=INDIRECT("B"&ROW()))),",")} -> SPAR Group-Server Project Design | N40: SPAR Group-Server Project Build and Migration
...

Sheet Archive
A1: Date | B1: Company | C1: Project Name | D1: Start Time | E1: End Time | F1: Short Description | G1: Detailed Description | H1: Project Activity | I1: Show Time As | J1: Location | K1: Logged
A2: 45922 | B2: Sylvan, Inc | C2: Sylvan-AVD Proof of Concept | D2: 12 | E2: 12.25 | F2: Reviewed vMX license availability | G2: Reviewed vMX license availability | H2: Engineering | I2: Assigned Project | J2: Sentinel or Home Office
A3: 45922 | B3: Atlas Healthcare Partners | C3: Atlas Healthcare Partners-Windows 365 Jumpstart | D3: 13.25 | E3: 13.5 | F3: Updated Blueprint | G3: Updated Blueprint | H3: Engineering | I3: Assigned Project | J3: Sentinel or Home Office
A4: 45922 | B4: Raintree Systems | C4: Fortis Cyber Security Delivery | D4: 13.75 | E4: 14.25 | F4: Updated KSM Key Policy | G4: Updated KSM Key Policy | H4: Engineering | I4: Assigned Project | J4: Sentinel or Home Office
A5: 45922 | B5: Credit Interlink | C5: Credit Interlink-Production to Azure Migration T_M | D5: 15 | E5: 15.75 | F5: Status Update Meeting | G5: Status Update Meeting | H5: Engineering | I5: Assigned Project | J5: Sentinel or Home Office
A6: 45922 | B6: NA | C6: NA | D6: 16 | E6: 16.25 | F6: AVS Audit Dry Run | G6: AVS Audit Dry Run | H6: Engineering | I6: Sales Support | J6: Sentinel or Home Office
A7: 45922 | B7: Atlas Healthcare Partners | C7: Atlas Healthcare Partners-Windows 365 Jumpstart | D7: 22 | E7: 22.25 | F7: Update vNet IP Space | G7: Update vNet IP Space | H7: Engineering | I7: Assigned Project | J7: Sentinel or Home Office
A8: 45923 | B8: Wahl Clipper Corp | C8: Wahl Clipper-Microsoft AVD | D8: 10.25 | E8: 10.5 | F8: Provide script for mounting file share | G8: Provide script for mounting file share | H8: Engineering | I8: Assigned Project | J8: Sentinel or Home Office
A9: 45923 | B9: WK Kellogg Co. | C9: WK Kellogg-AVD and Windows 365 | D9: 11.5 | E9: 12 | F9: EKO | G9: EKO | H9: Engineering | I9: Assigned Project | J9: Sentinel or Home Office
A10: 45923 | B10: Atlas Healthcare Partners | C10: Atlas Healthcare Partners-Windows 365 Jumpstart | D10: 13 | E10: 13.75 | F10: Update email to customer and PM, CIP and TAP created | G10: Update email to customer and PM, CIP and TAP created | H10: Engineering | I10: Assigned Project | J10: Sentinel or Home Office
A11: 45924 | B11: Sylvan, Inc | C11: Sylvan-AVD Proof of Concept | D11: 9.5 | E11: 10 | F11: Review vMX licensing options and send to customer | G11: Review vMX licensing options and send to customer | H11: Engineering | I11: Assigned Project | J11: Sentinel or Home Office
A12: 45924 | B12: NA | C12: NA | D12: 10 | E12: 12.5 | F12: Azure CoPilot Assessment Prep | G12: Azure CoPilot Assessment Prep | H12: Engineering | I12: Non- Billable Work Hours | J12: Sentinel or Home Office
A13: 45924 | B13: Atlas Healthcare Partners | C13: Atlas Healthcare Partners-Windows 365 Jumpstart | D13: 12.5 | E13: 12.75 | F13: PM Touchpoint | G13: PM Touchpoint | H13: Engineering | I13: Assigned Project | J13: Sentinel or Home Office
... A27: 45926 | B27: Atlas Healthcare Partners | C27: Atlas Healthcare Partners-Windows 365 Jumpstart | D27: 14.5 | E27: 17.5 | F27: Staging | G27: Staging | H27: Engineering | I27: Assigned Project | J27: Sentinel or Home Office
A28: 45929 | D28: 9 | E28: 9.5 | F28: Time Entry | G28: Time Entry | H28: Engineering | I28: Non- Billable Work Hours | J28: Sentinel or Home Office
A29: 45929 | D29: 9.5 | E29: 10 | F29: Applied Skills for CoPilot | G29: Applied Skills for CoPilot | H29: Engineering | I29: Non- Billable Work Hours | J29: Sentinel or Home Office
A30: 45929 | B30: Atlas Healthcare Partners | C30: Atlas Healthcare Partners-Windows 365 Jumpstart | D30: 10 | E30: 12 | F30: Update HST app in Intune, attempt application deployment, review network issues | G30: Update HST app in Intune, attempt application deployment, review network issues | H30: Engineering | I30: Assigned Project | J30: Sentinel or Home Office
A31: 45929 | B31: Sara Lee Frozen Bakery | C31: Sara Lee Frozen Bakery-Azure Assessment | D31: 11.5 | E31: 12.75 | F31: Review data collection. Have PM request Contributor credentials to create the assessment | G31: Review data collection. Have PM request Contributor credentials to create the assessment | H31: Engineering | I31: Assigned Project | J31: Sentinel or Home Office
A32: 45929 | B32: Atlas Healthcare Partners | C32: Atlas Healthcare Partners-Windows 365 Jumpstart | D32: 13 | E32: 14.5 | F32: Review and configure Intune | G32: Review and configure Intune | H32: Engineering | I32: Assigned Project | J32: Sentinel or Home Office
A33: 45929 | B33: Credit Interlink | C33: Credit Interlink-Production to Azure Migration T_M | D33: 15 | E33: 15.5 | F33: Status Update Meeting | G33: Status Update Meeting | H33: Engineering | I33: Assigned Project | J33: Sentinel or Home Office
A34: 45930 | D34: 9.5 | E34: 10 | F34: Team Meeting | G34: Team Meeting | I34: Non- Billable Work Hours | J34: Sentinel or Home Office
A35: 45930 | B35: Credit Interlink | C35: Credit Interlink-Production to Azure Migration T_M | D35: 11.5 | E35: 12.5 | F35: Disk Migration | G35: Disk Migration | H35: Engineering | I35: Assigned Project | J35: Sentinel or Home Office
A36: 45930 | D36: 10 | E36: 11.5 | F36: SC-300 Study | G36: SC-300 Study | I36: Non- Billable Work Hours | J36: Sentinel or Home Office
A37: 45930 | B37: WK Kellogg Co. | C37: WK Kellogg-AVD and Windows 365 | D37: 13 | E37: 13.25 | F37: Verify Access | G37: Verify Access | H37: Engineering | I37: Assigned Project | J37: Sentinel or Home Office
A38: 45930 | D38: 13.25 | E38: 14.5 | F38: SC300 Exam Prep | G38: SC300 Exam Prep | I38: Non- Billable Work Hours | J38: Sentinel or Home Office
A39: 45930 | B39: Atlas Healthcare Partners | C39: Atlas Healthcare Partners-Windows 365 Jumpstart | D39: 14.5 | E39: 17 | F39: Configure Intune | G39: Configure Intune | H39: Engineering | I39: Assigned Project | J39: Sentinel or Home Office
A40: 45931 | D40: 8 | E40: 9 | F40: SC-300 Exam Prep | G40: SC-300 Exam Prep | I40: Non- Billable Work Hours | J40: Sentinel or Home Office | M40: {=_xlfn.TEXTSPLIT(_xlfn.TEXTJOIN(",",TRUE,_xlfn._xlws.FILTER('Active Projects'!B:B, 'Active Projects'!A:A=INDIRECT("B"&ROW()))),",")} -> #VALUE!
A41: 45931 | B41: Atlas Healthcare Partners | C41: Atlas Healthcare Partners-Windows 365 Jumpstart | D41: 9 | E41: 10 | F41: Intune Enrollment | G41: Intune Enrollment | H41: Engineering | I41: Assigned Project | J41: Sentinel or Home Office | M41: {=_xlfn.TEXTSPLIT(_xlfn.TEXTJOIN(",",TRUE,_xlfn._xlws.FILTER('Active Projects'!B:B, 'Active Projects'!A:A=INDIRECT("B"&ROW()))),",")} -> Atlas Healthcare Partners-Windows 365 Jumpstart
A42: 45931 | D42: 10 | E42: 12 | F42: SC-300 Exam Prep | G42: SC-300 Exam Prep | I42: Non- Billable Work Hours | J42: Sentinel or Home Office | M42: {=_xlfn.TEXTSPLIT(_xlfn.TEXTJOIN(",",TRUE,_xlfn._xlws.FILTER('Active Projects'!B:B, 'Active Projects'!A:A=INDIRECT("B"&ROW()))),",")} -> #VALUE!
A43: 45931 | D43: 13 | E43: 16 | F43: SC-300 Exam | G43: SC-300 Exam | I43: Non- Billable Work Hours | J43: Sentinel or Home Office | M43: {=_xlfn.TEXTSPLIT(_xlfn.TEXTJOIN(",",TRUE,_xlfn._xlws.FILTER('Active Projects'!B:B, 'Active Projects'!A:A=INDIRECT("B"&ROW()))),",")} -> #VALUE!
A44: 45931 | D44: 16 | E44: 17 | F44: MS-102 Study | G44: MS-102 Exam | I44: Non- Billable Work Hours | J44: Sentinel or Home Office | M44: {=_xlfn.TEXTSPLIT(_xlfn.TEXTJOIN(",",TRUE,_xlfn._xlws.FILTER('Active Projects'!B:B, 'Active Projects'!A:A=INDIRECT("B"&ROW()))),",")} -> #VALUE!
A45: 45932 | B45: WK Kellogg Co. | C45: WK Kellogg-AVD and Windows 365 | D45: 9 | E45: 13.5 | F45: Discovery | G45: Discovery | H45: Engineering | I45: Assigned Project | J45: Sentinel or Home Office | M45: {=_xlfn.TEXTSPLIT(_xlfn.TEXTJOIN(",",TRUE,_xlfn._xlws.FILTER('Active Projects'!B:B, 'Active Projects'!A:A=INDIRECT("B"&ROW()))),",")} -> WK Kellogg-AVD and Windows 365
A46: 45932 | D46: 11.5 | E46: 12 | F46: MS Audit Review | G46: MS Audit Review | I46: Sales Support | J46: Sentinel or Home Office | M46: {=_xlfn.TEXTSPLIT(_xlfn.TEXTJOIN(",",TRUE,_xlfn._xlws.FILTER('Active Projects'!B:B, 'Active Projects'!A:A=INDIRECT("B"&ROW()))),",")} -> #VALUE!
A47: 45932 | B47: WK Kellogg Co. | C47: WK Kellogg-AVD and Windows 365 | D47: 14.5 | E47: 17 | F47: Discovery | G47: Discovery | H47: Engineering | I47: Assigned Project | J47: Sentinel or Home Office | M47: {=_xlfn.TEXTSPLIT(_xlfn.TEXTJOIN(",",TRUE,_xlfn._xlws.FILTER('Active Projects'!B:B, 'Active Projects'!A:A=INDIRECT("B"&ROW()))),",")} -> WK Kellogg-AVD and Windows 365
A48: 45933 | B48: WK Kellogg Co. | C48: WK Kellogg-AVD and Windows 365 | D48: 8.75 | E48: 9.5 | F48: Discovery | G48: Discovery | H48: Engineering | I48: Assigned Project | J48: Sentinel or Home Office | M48: {=_xlfn.TEXTSPLIT(_xlfn.TEXTJOIN(",",TRUE,_xlfn._xlws.FILTER('Active Projects'!B:B, 'Active Projects'!A:A=INDIRECT("B"&ROW()))),",")} -> WK Kellogg-AVD and Windows 365
A49: 45933 | B49: Credit Interlink | C49: Credit Interlink-Production to Azure Migration T_M | D49: 9.5 | E49: 11.5 | F49: APIM discovery call | G49: APIM discovery call | H49: Engineering | I49: Assigned Project | J49: Sentinel or Home Office | M49: {=_xlfn.TEXTSPLIT(_xlfn.TEXTJOIN(",",TRUE,_xlfn._xlws.FILTER('Active Projects'!B:B, 'Active Projects'!A:A=INDIRECT("B"&ROW()))),",")} -> Credit Interlink-Production to Azure Migration T_M | N49: Credit Interlink-DR_HA Configuration
A50: 45933 | B50: WK Kellogg Co. | C50: WK Kellogg-AVD and Windows 365 | D50: 11.5 | E50: 12 | F50: Setup Monitoring for Log Insights and status meeting | G50: Setup Monitoring for Log Insights and status meeting | H50: Engineering | I50: Assigned Project | J50: Sentinel or Home Office | M50: {=_xlfn.TEXTSPLIT(_xlfn.TEXTJOIN(",",TRUE,_xlfn._xlws.FILTER('Active Projects'!B:B, 'Active Projects'!A:A=INDIRECT("B"&ROW()))),",")} -> WK Kellogg-AVD and Windows 365
A51: 45933 | B51: Brightstar Care | C51: Brightstar Care-Azure Network Services | D51: 13.25 | E51: 14 | F51: IKO | G51: IKO | H51: Engineering | I51: Assigned Project | J51: Sentinel or Home Office | M51: {=_xlfn.TEXTSPLIT(_xlfn.TEXTJOIN(",",TRUE,_xlfn._xlws.FILTER('Active Projects'!B:B, 'Active Projects'!A:A=INDIRECT("B"&ROW()))),",")} -> Brightstar Care-Azure Network Services | N51: Brightstar Care-Azure Network Services Review Calls
A52: 45933 | B52: WK Kellogg Co. | C52: WK Kellogg-AVD and Windows 365 | D52: 14 | E52: 15.5 | F52: Configure hosts for monitoring | G52: Configure hosts for monitoring | H52: Engineering | I52: Assigned Project | J52: Sentinel or Home Office | M52: {=_xlfn.TEXTSPLIT(_xlfn.TEXTJOIN(",",TRUE,_xlfn._xlws.FILTER('Active Projects'!B:B, 'Active Projects'!A:A=INDIRECT("B"&ROW()))),",")} -> WK Kellogg-AVD and Windows 365
A53: 45936 | B53: WK Kellogg Co. | C53: WK Kellogg-AVD and Windows 365 | D53: 9 | E53: 11.25 | F53: Review Metrics and Data Collection | G53: Review Metrics and Data Collection | H53: Engineering | I53: Assigned Project | J53: Sentinel or Home Office | M53: {=_xlfn.TEXTSPLIT(_xlfn.TEXTJOIN(",",TRUE,_xlfn._xlws.FILTER('Active Projects'!B:B, 'Active Projects'!A:A=INDIRECT("B"&ROW()))),",")} -> WK Kellogg-AVD and Windows 365
...

Sheet Active Projects
A1: Company | B1: Project | C1: PM | D1: SA | E1: AM
A2: Atlas Healthcare Partners | B2: Atlas Healthcare Partners-Windows 365 Jumpstart | C2: Doug
A3: Aurorium | B3: Aurorium-Azure Services | C3: Tamara | D3: Ed
A4: Brightstar Care | B4: Brightstar Care-Azure Network Services | C4: Tamara
A5: Brightstar Care | B5: Brightstar Care-Azure Network Services Review Calls | C5: Tamara
A6: City Of Des Plaines | B6: City of Des Plaines-Azure Domain Controller Migration | C6: Dan
A7: Clark County Library District | B7: Clark County Library District-Azure Accelerate Assessment | C7: Brie
A8: Credit Interlink | B8: Credit Interlink-Production to Azure Migration T_M | C8: Dave
A9: Floracraft | B9: Floracraft-Azure Landing Zone | C9: Mychaela
A10: Floracraft | B10: Floracraft-Azure Server Migrations | C10: Mychaela
A11: L.E.K. Consulting LLC | B11: L.E.K Consulting-Azure Networking Assessment | C11: Stew
A12: NA | B12: NA
A13: National Council of State Boards of Nursing | B13: National Council of State Boards of Nursing-Microsoft Resource | C13: Sunshine
A14: Peckham Inc | B14: Peckham-Microsoft Azure Consulting & LZ Validation | C14: Jennifer
A15: Qcr Holdings Inc | B15: QCR Holdings-Azure Event Hub | C15: Tamara | D15: Soule
A16: Raintree Systems | B16: Fortis Cyber Security Delivery | C16: Kent
A17: Sales Support | B17: Sales Support
A18: Sara Lee Frozen Bakery | B18: Sara Lee Frozen Bakery-Azure Assessment | C18: Brie
A19: Silver Cross Hospital | B19: Silver Cross Hospital-Redcap Azure Configuration | C19: Dan
A20: SimonMed | B20: Fortis Cyber Security Delivery | C20: Kent
A21: SPAR Group Inc | B21: SPAR Group-Server Project Design | C21: Jennifer
A22: SPAR Group Inc | B22: SPAR Group-Server Project Build and Migration | C22: Jennifer
A23: Sylvan, Inc | B23: Sylvan-AVD Proof of Concept | C23: Alex
A24: Wahl Clipper Corp | B24: Wahl Clipper-Microsoft AVD | C24: Brie
A25: WK Kellogg Co. | B25: WK Kellogg-AVD and Windows 365 | C25: Melissa
A26: Credit Interlink | B26: Credit Interlink-DR_HA Configuration | C26: Dave | D26: Ed
A27: Bradford Exchange Limited | B27: Bradford Exchange Ltd-Azure Land Zone-Discovery_Workshops_Documentation | C27: George Garbis
A28: Bradford Exchange Limited | B28: Bradford Exchange Ltd-Azure Land Zone-All Remaining Phases | C28: George Garbis | D28: Justin Coffey | E28: Kyle Donnelly
A29: cr Holdings Inc | B29: QCR Holdings-Azure Event Hub | C29: Tamara | D29: Soule

Sheet Data Validation
A1: Show Time As | B1: Location
A2: Assigned Project | B2: Sentinel or Home Office
A3: Non- Billable Work Hours | B3: Customer Facility
A4: Project Not Listed
A5: Sales Support
A6: Support Operations
A7: Out of Town Travel
A8: Non-Billable Work Hours
